<?xml version="1.0" ?>
<robot name="BiStable" xmlns:xacro="http://www.ros.org/wiki/xacro">

<xacro:include filename="$(find BiStable_description)/urdf/materials.xacro" />
<xacro:include filename="$(find BiStable_description)/urdf/BiStable.trans" />
<xacro:include filename="$(find BiStable_description)/urdf/BiStable.gazebo" />

<link name="base_footprint"/>

<link name="base_link">
  <inertial>
    <origin xyz="0.0 0.0013351749539594884 0.11189226519337016" rpy="0 0 0"/>
    <mass value="0.710425"/>
    <inertia ixx="0.002959" iyy="0.002883" izz="0.000124" ixy="0.0" iyz="-8.6e-05" ixz="0.0"/>
  </inertial>
  <visual>
    <origin xyz="0 0 0" rpy="0 0 0"/>
    <geometry>
      <mesh filename="file://$(find BiStable_description)/meshes/base_link.stl" scale="0.001 0.001 0.001"/>
    </geometry>
    <material name="silver"/>
  </visual>
  <collision>
    <origin xyz="0 0 0" rpy="0 0 0"/>
    <geometry>
      <mesh filename="file://$(find BiStable_description)/meshes/base_link.stl" scale="0.001 0.001 0.001"/>
    </geometry>
  </collision>
</link>

<link name="right_stepper_1">
  <inertial>
    <origin xyz="0.016940372677690052 -4.805080613014999e-18 -0.0815000000000334" rpy="0 0 0"/>
    <mass value="0.46432190632670445"/>
    <inertia ixx="0.000133" iyy="0.000113" izz="0.000113" ixy="-0.0" iyz="0.0" ixz="0.0"/>
  </inertial>
  <visual>
    <origin xyz="-0.01 -0.0 -0.1025" rpy="0 0 0"/>
    <geometry>
      <mesh filename="file://$(find BiStable_description)/meshes/right_stepper_1.stl" scale="0.001 0.001 0.001"/>
    </geometry>
    <material name="silver"/>
  </visual>
  <collision>
    <origin xyz="-0.01 -0.0 -0.1025" rpy="0 0 0"/>
    <geometry>
      <mesh filename="file://$(find BiStable_description)/meshes/right_stepper_1.stl" scale="0.001 0.001 0.001"/>
    </geometry>
  </collision>
</link>

<link name="left_stepper_1">
  <inertial>
    <origin xyz="-0.01694037267769006 -2.4025403065054546e-18 -0.08149999999996663" rpy="0 0 0"/>
    <mass value="0.4643219063267044"/>
    <inertia ixx="0.000133" iyy="0.000113" izz="0.000113" ixy="0.0" iyz="-0.0" ixz="0.0"/>
  </inertial>
  <visual>
    <origin xyz="0.01 -0.0 -0.1025" rpy="0 0 0"/>
    <geometry>
      <mesh filename="file://$(find BiStable_description)/meshes/left_stepper_1.stl" scale="0.001 0.001 0.001"/>
    </geometry>
    <material name="silver"/>
  </visual>
  <collision>
    <origin xyz="0.01 -0.0 -0.1025" rpy="0 0 0"/>
    <geometry>
      <mesh filename="file://$(find BiStable_description)/meshes/left_stepper_1.stl" scale="0.001 0.001 0.001"/>
    </geometry>
  </collision>
</link>

<link name="right_wheel_1">
  <inertial>
    <origin xyz="0.0024425287356322073 0.0005005443351473899 -3.6290415117434804e-15" rpy="0 0 0"/>
    <mass value="0.19309956324922345"/>
    <inertia ixx="0.000156" iyy="7.9e-05" izz="7.7e-05" ixy="-0.0" iyz="-0.0" ixz="-0.0"/>
  </inertial>
  <visual>
    <origin xyz="-0.067 0.0 -0.021" rpy="0 0 0"/>
    <geometry>
      <mesh filename="file://$(find BiStable_description)/meshes/right_wheel_1.stl" scale="0.001 0.001 0.001"/>
    </geometry>
    <material name="silver"/>
  </visual>
  <collision>
    <origin xyz="-0.067 0.0 -0.021" rpy="0 0 0"/>
    <geometry>
      <mesh filename="file://$(find BiStable_description)/meshes/right_wheel_1.stl" scale="0.001 0.001 0.001"/>
    </geometry>
  </collision>
</link>

<link name="left_wheel_1">
  <inertial>
    <origin xyz="-0.0024425287356322073 -1.7392546308187155e-17 0.0005005443351510167" rpy="0 0 0"/>
    <mass value="0.1930995632492234"/>
    <inertia ixx="0.000156" iyy="7.7e-05" izz="7.9e-05" ixy="-0.0" iyz="0.0" ixz="0.0"/>
  </inertial>
  <visual>
    <origin xyz="0.067 -0.0 -0.021" rpy="0 0 0"/>
    <geometry>
      <mesh filename="file://$(find BiStable_description)/meshes/left_wheel_1.stl" scale="0.001 0.001 0.001"/>
    </geometry>
    <material name="silver"/>
  </visual>
  <collision>
    <origin xyz="0.067 -0.0 -0.021" rpy="0 0 0"/>
    <geometry>
      <mesh filename="file://$(find BiStable_description)/meshes/left_wheel_1.stl" scale="0.001 0.001 0.001"/>
    </geometry>
  </collision>
</link>

<link name="rpi_1">
  <inertial>
    <origin xyz="-0.0075000000000000015 0.0 0.030000000000000013" rpy="0 0 0"/>
    <mass value="0.7064999999999999"/>
    <inertia ixx="0.000801" iyy="0.000602" izz="0.000225" ixy="0.0" iyz="0.0" ixz="-0.0"/>
  </inertial>
  <visual>
    <origin xyz="0.01 -0.0 -0.1025" rpy="0 0 0"/>
    <geometry>
      <mesh filename="file://$(find BiStable_description)/meshes/rpi_1.stl" scale="0.001 0.001 0.001"/>
    </geometry>
    <material name="silver"/>
  </visual>
  <collision>
    <origin xyz="0.01 -0.0 -0.1025" rpy="0 0 0"/>
    <geometry>
      <mesh filename="file://$(find BiStable_description)/meshes/rpi_1.stl" scale="0.001 0.001 0.001"/>
    </geometry>
  </collision>
</link>

<link name="NUCLEO_1">
  <inertial>
    <origin xyz="0.0075000000000000015 0.0 0.030000000000000013" rpy="0 0 0"/>
    <mass value="0.7064999999999999"/>
    <inertia ixx="0.000801" iyy="0.000602" izz="0.000225" ixy="0.0" iyz="0.0" ixz="0.0"/>
  </inertial>
  <visual>
    <origin xyz="-0.01 -0.0 -0.1025" rpy="0 0 0"/>
    <geometry>
      <mesh filename="file://$(find BiStable_description)/meshes/NUCLEO_1.stl" scale="0.001 0.001 0.001"/>
    </geometry>
    <material name="silver"/>
  </visual>
  <collision>
    <origin xyz="-0.01 -0.0 -0.1025" rpy="0 0 0"/>
    <geometry>
      <mesh filename="file://$(find BiStable_description)/meshes/NUCLEO_1.stl" scale="0.001 0.001 0.001"/>
    </geometry>
  </collision>
</link>

<joint name="base_footprint_link" type="fixed">
  <parent link="base_footprint"/>
  <child link="base_link"/>
  <origin xyz="0.0 0.0 0.019" rpy="0.0 0.0 0.0"/>
</joint>

<joint name="Rigid 17" type="fixed">
  <origin xyz="0.01 0.0 0.1025" rpy="0 0 0"/>
  <parent link="base_link"/>
  <child link="right_stepper_1"/>
</joint>

<joint name="Rigid 18" type="fixed">
  <origin xyz="-0.01 0.0 0.1025" rpy="0 0 0"/>
  <parent link="base_link"/>
  <child link="left_stepper_1"/>
</joint>

<joint name="Revolute 19" type="continuous">
  <origin xyz="0.057 -0.0 -0.0815" rpy="0 0 0"/>
  <parent link="right_stepper_1"/>
  <child link="right_wheel_1"/>
  <axis xyz="1.0 0.0 0.0"/>
</joint>

<joint name="Revolute 20" type="continuous">
  <origin xyz="-0.057 0.0 -0.0815" rpy="0 0 0"/>
  <parent link="left_stepper_1"/>
  <child link="left_wheel_1"/>
  <axis xyz="-1.0 0.0 0.0"/>
</joint>

<joint name="Rigid 21" type="fixed">
  <origin xyz="-0.01 0.0 0.1025" rpy="0 0 0"/>
  <parent link="base_link"/>
  <child link="rpi_1"/>
</joint>

<joint name="Rigid 22" type="fixed">
  <origin xyz="0.01 0.0 0.1025" rpy="0 0 0"/>
  <parent link="base_link"/>
  <child link="NUCLEO_1"/>
</joint>

</robot>
